<!--
 * @Author: liming
 * @Date: 2021-07-31 13:03:31
 * @LastEditTime: 2021-07-31 13:08:54
 * @FilePath: \01-尚硅谷李强\02-代码手敲\01-Promise的基本使用\08-Promise的API-resolve和reject.html
-->
<!DOCTYPE html>
<html lang="en">
<head>
    <meta charset="UTF-8">
    <meta http-equiv="X-UA-Compatible" content="IE=edge">
    <meta name="viewport" content="width=device-width, initial-scale=1.0">
    <title>Document</title>
</head>
<body>
    <script>
        let p1 = Promise.resolve(521)
        //如果传入的参数为非promise类型的对象，则返回的结果都为成功Promise对象
        //如果传入的参数为promise对象，则参数的结果决定了resolve的结果
        console.log(p1);

        let p2 = Promise.resolve(new Promise((resolve, reject)=>{
            // resolve('OK')
            reject('Error')
            //报错：Uncaught (in promise) Error
            //原因：我们这里有一个失败的Promise，而且还没有一个结果对失败进行处理，所以会报错
        }))
        p2.catch(reason => {
            console.log(reason);
        })
        console.log(p2);
    </script>
</body>
</html>